ðŸ”¹ Pulling the image ostorlab.store/agents/agent_5448_inject_asset from the ostorlab store.

âœ” Installation successful
ðŸ”¹ Pulling the image ostorlab.store/agents/agent_5448_tracker from the ostorlab store.

âœ” Installation successful
ðŸ”¹ Pulling the image ostorlab.store/agents/agent_5448_local_persist_vulnz from the ostorlab store.

âœ” Installation successful
ðŸ”¹ Pulling the image ostorlab.store/agents/agent_5448_amass from the ostorlab store.

âœ” Installation successful
ðŸ”¹ Pulling the image ostorlab.store/agents/agent_5448_subfinder from the ostorlab store.

âœ” Installation successful
ðŸ”¹ Pulling the image ostorlab.store/agents/agent_5448_tsunami from the ostorlab store.

âœ” Installation successful
ðŸ”¹ Pulling the image ostorlab.store/agents/agent_5448_nmap from the ostorlab store.

âœ” Installation successful
ðŸ”¹ Pulling the image ostorlab.store/agents/agent_5448_asteroid from the ostorlab store.

âœ” Installation successful
ðŸ”¹ Pulling the image ostorlab.store/agents/agent_5448_nuclei from the ostorlab store.

âœ” Installation successful
ðŸ”¹ Pulling the image ostorlab.store/agents/agent_5448_metasploit from the ostorlab store.

âœ” Installation successful
ðŸ”¹ Creating scan entry
ðŸ”¹ Creating network
ðŸ”¹ Starting services
ðŸ”¹ Checking services are healthy
ðŸ”¹ Starting pre-agents
ðŸ”¹ Checking pre-agents are healthy
ðŸ”¹ Starting agents
ðŸ”¹ Checking agents are healthy
ðŸ”¹ Injecting asset: 192.168.0.24/32
ðŸ”¹ Updating scan status
ðŸ”¹ Starting post-agents
ðŸ”¹ Checking post-agents are healthy
Traceback (most recent call last):
  File "/usr/lib/python3.11/site-packages/urllib3/connectionpool.py", line 466, in _make_request
    six.raise_from(e, None)
  File "<string>", line 3, in raise_from
  File "/usr/lib/python3.11/site-packages/urllib3/connectionpool.py", line 461, in _make_request
    httplib_response = conn.getresponse()
                       ^^^^^^^^^^^^^^^^^^
  File "/usr/lib64/python3.11/http/client.py", line 1378, in getresponse
    response.begin()
  File "/usr/lib64/python3.11/http/client.py", line 318, in begin
    version, status, reason = self._read_status()
                              ^^^^^^^^^^^^^^^^^^^
  File "/usr/lib64/python3.11/http/client.py", line 279, in _read_status
    line = str(self.fp.readline(_MAXLINE + 1), "iso-8859-1")
               ^^^^^^^^^^^^^^^^^^^^^^^^^^^^^^
  File "/usr/lib64/python3.11/socket.py", line 706, in readinto
    return self._sock.recv_into(b)
           ^^^^^^^^^^^^^^^^^^^^^^^
TimeoutError: timed out

During handling of the above exception, another exception occurred:

Traceback (most recent call last):
  File "/usr/lib/python3.11/site-packages/requests/adapters.py", line 489, in send
    resp = conn.urlopen(
           ^^^^^^^^^^^^^
  File "/usr/lib/python3.11/site-packages/urllib3/connectionpool.py", line 798, in urlopen
    retries = retries.increment(
              ^^^^^^^^^^^^^^^^^^
  File "/usr/lib/python3.11/site-packages/urllib3/util/retry.py", line 550, in increment
    raise six.reraise(type(error), error, _stacktrace)
          ^^^^^^^^^^^^^^^^^^^^^^^^^^^^^^^^^^^^^^^^^^^^
  File "/usr/lib/python3.11/site-packages/urllib3/packages/six.py", line 719, in reraise
    raise value
  File "/usr/lib/python3.11/site-packages/urllib3/connectionpool.py", line 714, in urlopen
    httplib_response = self._make_request(
                       ^^^^^^^^^^^^^^^^^^^
  File "/usr/lib/python3.11/site-packages/urllib3/connectionpool.py", line 468, in _make_request
    self._raise_timeout(err=e, url=url, timeout_value=read_timeout)
  File "/usr/lib/python3.11/site-packages/urllib3/connectionpool.py", line 357, in _raise_timeout
    raise ReadTimeoutError(
urllib3.exceptions.ReadTimeoutError: UnixHTTPConnectionPool(host='localhost', port=None): Read timed out. (read timeout=60)

During handling of the above exception, another exception occurred:

Traceback (most recent call last):
  File "/home/keith/.local/bin/ostorlab", line 8, in <module>
    sys.exit(main())
             ^^^^^^
  File "/home/keith/.local/lib/python3.11/site-packages/ostorlab/__init__.py", line 27, in main
    rootcli(None)
  File "/usr/lib/python3.11/site-packages/click/core.py", line 1130, in __call__
    return self.main(*args, **kwargs)
           ^^^^^^^^^^^^^^^^^^^^^^^^^^
  File "/usr/lib/python3.11/site-packages/click/core.py", line 1055, in main
    rv = self.invoke(ctx)
         ^^^^^^^^^^^^^^^^
  File "/usr/lib/python3.11/site-packages/click/core.py", line 1657, in invoke
    return _process_result(sub_ctx.command.invoke(sub_ctx))
                           ^^^^^^^^^^^^^^^^^^^^^^^^^^^^^^^
  File "/usr/lib/python3.11/site-packages/click/core.py", line 1657, in invoke
    return _process_result(sub_ctx.command.invoke(sub_ctx))
                           ^^^^^^^^^^^^^^^^^^^^^^^^^^^^^^^
  File "/usr/lib/python3.11/site-packages/click/core.py", line 1657, in invoke
    return _process_result(sub_ctx.command.invoke(sub_ctx))
                           ^^^^^^^^^^^^^^^^^^^^^^^^^^^^^^^
  File "/usr/lib/python3.11/site-packages/click/core.py", line 1404, in invoke
    return ctx.invoke(self.callback, **ctx.params)
           ^^^^^^^^^^^^^^^^^^^^^^^^^^^^^^^^^^^^^^^
  File "/usr/lib/python3.11/site-packages/click/core.py", line 760, in invoke
    return __callback(*args, **kwargs)
           ^^^^^^^^^^^^^^^^^^^^^^^^^^^
  File "/usr/lib/python3.11/site-packages/click/decorators.py", line 26, in new_func
    return f(get_current_context(), *args, **kwargs)
           ^^^^^^^^^^^^^^^^^^^^^^^^^^^^^^^^^^^^^^^^^
  File "/home/keith/.local/lib/python3.11/site-packages/ostorlab/cli/scan/run/assets/ip.py", line 47, in ip_cli
    runtime.scan(
  File "/home/keith/.local/lib/python3.11/site-packages/ostorlab/runtimes/local/runtime.py", line 224, in scan
    is_healthy = self._check_agents_healthy()
                 ^^^^^^^^^^^^^^^^^^^^^^^^^^^^
  File "/home/keith/.local/lib/python3.11/site-packages/ostorlab/runtimes/local/runtime.py", line 377, in _check_agents_healthy
    return self._are_agents_ready()
           ^^^^^^^^^^^^^^^^^^^^^^^^
  File "/home/keith/.local/lib/python3.11/site-packages/tenacity/__init__.py", line 289, in wrapped_f
    return self(f, *args, **kw)
           ^^^^^^^^^^^^^^^^^^^^
  File "/home/keith/.local/lib/python3.11/site-packages/tenacity/__init__.py", line 379, in __call__
    do = self.iter(retry_state=retry_state)
         ^^^^^^^^^^^^^^^^^^^^^^^^^^^^^^^^^^
  File "/home/keith/.local/lib/python3.11/site-packages/tenacity/__init__.py", line 314, in iter
    return fut.result()
           ^^^^^^^^^^^^
  File "/usr/lib64/python3.11/concurrent/futures/_base.py", line 449, in result
    return self.__get_result()
           ^^^^^^^^^^^^^^^^^^^
  File "/usr/lib64/python3.11/concurrent/futures/_base.py", line 401, in __get_result
    raise self._exception
  File "/home/keith/.local/lib/python3.11/site-packages/tenacity/__init__.py", line 382, in __call__
    result = fn(*args, **kwargs)
             ^^^^^^^^^^^^^^^^^^^
  File "/home/keith/.local/lib/python3.11/site-packages/ostorlab/runtimes/local/runtime.py", line 573, in _are_agents_ready
    if self._is_service_healthy(service):
       ^^^^^^^^^^^^^^^^^^^^^^^^^^^^^^^^^
  File "/home/keith/.local/lib/python3.11/site-packages/tenacity/__init__.py", line 289, in wrapped_f
    return self(f, *args, **kw)
           ^^^^^^^^^^^^^^^^^^^^
  File "/home/keith/.local/lib/python3.11/site-packages/tenacity/__init__.py", line 379, in __call__
    do = self.iter(retry_state=retry_state)
         ^^^^^^^^^^^^^^^^^^^^^^^^^^^^^^^^^^
  File "/home/keith/.local/lib/python3.11/site-packages/tenacity/__init__.py", line 314, in iter
    return fut.result()
           ^^^^^^^^^^^^
  File "/usr/lib64/python3.11/concurrent/futures/_base.py", line 449, in result
    return self.__get_result()
           ^^^^^^^^^^^^^^^^^^^
  File "/usr/lib64/python3.11/concurrent/futures/_base.py", line 401, in __get_result
    raise self._exception
  File "/home/keith/.local/lib/python3.11/site-packages/tenacity/__init__.py", line 382, in __call__
    result = fn(*args, **kwargs)
             ^^^^^^^^^^^^^^^^^^^
  File "/home/keith/.local/lib/python3.11/site-packages/ostorlab/runtimes/local/runtime.py", line 451, in _is_service_healthy
    for task in service.tasks()
                ^^^^^^^^^^^^^^^
  File "/home/keith/.local/lib/python3.11/site-packages/docker/models/services.py", line 54, in tasks
    return self.client.api.tasks(filters=filters)
           ^^^^^^^^^^^^^^^^^^^^^^^^^^^^^^^^^^^^^^
  File "/home/keith/.local/lib/python3.11/site-packages/docker/utils/decorators.py", line 32, in wrapper
    return f(self, *args, **kwargs)
           ^^^^^^^^^^^^^^^^^^^^^^^^
  File "/home/keith/.local/lib/python3.11/site-packages/docker/api/service.py", line 365, in tasks
    return self._result(self._get(url, params=params), True)
                        ^^^^^^^^^^^^^^^^^^^^^^^^^^^^^
  File "/home/keith/.local/lib/python3.11/site-packages/docker/utils/decorators.py", line 44, in inner
    return f(self, *args, **kwargs)
           ^^^^^^^^^^^^^^^^^^^^^^^^
  File "/home/keith/.local/lib/python3.11/site-packages/docker/api/client.py", line 236, in _get
    return self.get(url, **self._set_request_timeout(kwargs))
           ^^^^^^^^^^^^^^^^^^^^^^^^^^^^^^^^^^^^^^^^^^^^^^^^^^
  File "/usr/lib/python3.11/site-packages/requests/sessions.py", line 602, in get
    return self.request("GET", url, **kwargs)
           ^^^^^^^^^^^^^^^^^^^^^^^^^^^^^^^^^^
  File "/usr/lib/python3.11/site-packages/requests/sessions.py", line 589, in request
    resp = self.send(prep, **send_kwargs)
           ^^^^^^^^^^^^^^^^^^^^^^^^^^^^^^
  File "/usr/lib/python3.11/site-packages/requests/sessions.py", line 703, in send
    r = adapter.send(request, **kwargs)
        ^^^^^^^^^^^^^^^^^^^^^^^^^^^^^^^
  File "/usr/lib/python3.11/site-packages/requests/adapters.py", line 578, in send
    raise ReadTimeout(e, request=request)
requests.exceptions.ReadTimeout: UnixHTTPConnectionPool(host='localhost', port=None): Read timed out. (read timeout=60)
